Traceback (most recent call last):
  File "G:\Database\Mining_Equipment_management\backend\manage.py", line 23, in <module>
    main()
    ~~~~^^
  File "G:\Database\Mining_Equipment_management\backend\manage.py", line 19, in main
    execute_from_command_line(sys.argv)
    ~~~~~~~~~~~~~~~~~~~~~~~~~^^^^^^^^^^
  File "G:\Database\Mining_Equipment_management\.venv\Lib\site-packages\django\core\management\__init__.py", line 442, in execute_from_command_line
    utility.execute()
    ~~~~~~~~~~~~~~~^^
  File "G:\Database\Mining_Equipment_management\.venv\Lib\site-packages\django\core\management\__init__.py", line 436, in execute
    self.fetch_command(subcommand).run_from_argv(self.argv)
    ~~~~~~~~~~~~~~~~~~~~~~~~~~~~~~~~~~~~~~~~~~~~^^^^^^^^^^^
  File "G:\Database\Mining_Equipment_management\.venv\Lib\site-packages\django\core\management\commands\test.py", line 24, in run_from_argv
    super().run_from_argv(argv)
    ~~~~~~~~~~~~~~~~~~~~~^^^^^^
  File "G:\Database\Mining_Equipment_management\.venv\Lib\site-packages\django\core\management\base.py", line 413, in run_from_argv
    self.execute(*args, **cmd_options)
    ~~~~~~~~~~~~^^^^^^^^^^^^^^^^^^^^^^
  File "G:\Database\Mining_Equipment_management\.venv\Lib\site-packages\django\core\management\base.py", line 459, in execute
    output = self.handle(*args, **options)
  File "G:\Database\Mining_Equipment_management\.venv\Lib\site-packages\django\core\management\commands\test.py", line 63, in handle
    failures = test_runner.run_tests(test_labels)
  File "G:\Database\Mining_Equipment_management\.venv\Lib\site-packages\django\test\runner.py", line 1059, in run_tests
    suite = self.build_suite(test_labels)
  File "G:\Database\Mining_Equipment_management\.venv\Lib\site-packages\django\test\runner.py", line 914, in build_suite
    tests = self.load_tests_for_label(label, discover_kwargs)
  File "G:\Database\Mining_Equipment_management\.venv\Lib\site-packages\django\test\runner.py", line 895, in load_tests_for_label
    tests = self.test_loader.discover(start_dir=label, **kwargs)
  File "C:\Users\Admin\AppData\Local\Programs\Python\Python313\Lib\unittest\loader.py", line 310, in discover
    tests = list(self._find_tests(start_dir, pattern))
  File "C:\Users\Admin\AppData\Local\Programs\Python\Python313\Lib\unittest\loader.py", line 374, in _find_tests
    yield from self._find_tests(full_path, pattern)
  File "C:\Users\Admin\AppData\Local\Programs\Python\Python313\Lib\unittest\loader.py", line 374, in _find_tests
    yield from self._find_tests(full_path, pattern)
  File "C:\Users\Admin\AppData\Local\Programs\Python\Python313\Lib\unittest\loader.py", line 366, in _find_tests
    tests, should_recurse = self._find_test_path(full_path, pattern)
                            ~~~~~~~~~~~~~~~~~~~~^^^^^^^^^^^^^^^^^^^^
  File "C:\Users\Admin\AppData\Local\Programs\Python\Python313\Lib\unittest\loader.py", line 418, in _find_test_path
    raise ImportError(
        msg % (mod_name, module_dir, expected_dir))
ImportError: 'tests' module incorrectly imported from 'G:\\Database\\Mining_Equipment_management\\backend\\apps\\wear_part_stock\\tests'. Expected 'G:\\Database\\Mining_Equipment_management\\backend\\apps\\wear_part_stock'. Is this module globally installed?
